['http://udc-aj38-17c1:5000/{}']
Traceback (most recent call last):
  File "/home/sms8fr/.conda/envs/model/lib/python3.7/site-packages/urllib3/connection.py", line 175, in _new_conn
    (self._dns_host, self.port), self.timeout, **extra_kw
  File "/home/sms8fr/.conda/envs/model/lib/python3.7/site-packages/urllib3/util/connection.py", line 95, in create_connection
    raise err
  File "/home/sms8fr/.conda/envs/model/lib/python3.7/site-packages/urllib3/util/connection.py", line 85, in create_connection
    sock.connect(sa)
ConnectionRefusedError: [Errno 111] Connection refused

During handling of the above exception, another exception occurred:

Traceback (most recent call last):
  File "/home/sms8fr/.conda/envs/model/lib/python3.7/site-packages/urllib3/connectionpool.py", line 710, in urlopen
    chunked=chunked,
  File "/home/sms8fr/.conda/envs/model/lib/python3.7/site-packages/urllib3/connectionpool.py", line 398, in _make_request
    conn.request(method, url, **httplib_request_kw)
  File "/home/sms8fr/.conda/envs/model/lib/python3.7/site-packages/urllib3/connection.py", line 239, in request
    super(HTTPConnection, self).request(method, url, body=body, headers=headers)
  File "/home/sms8fr/.conda/envs/model/lib/python3.7/http/client.py", line 1252, in request
    self._send_request(method, url, body, headers, encode_chunked)
  File "/home/sms8fr/.conda/envs/model/lib/python3.7/http/client.py", line 1298, in _send_request
    self.endheaders(body, encode_chunked=encode_chunked)
  File "/home/sms8fr/.conda/envs/model/lib/python3.7/http/client.py", line 1247, in endheaders
    self._send_output(message_body, encode_chunked=encode_chunked)
  File "/home/sms8fr/.conda/envs/model/lib/python3.7/http/client.py", line 1026, in _send_output
    self.send(msg)
  File "/home/sms8fr/.conda/envs/model/lib/python3.7/http/client.py", line 966, in send
    self.connect()
  File "/home/sms8fr/.conda/envs/model/lib/python3.7/site-packages/urllib3/connection.py", line 205, in connect
    conn = self._new_conn()
  File "/home/sms8fr/.conda/envs/model/lib/python3.7/site-packages/urllib3/connection.py", line 187, in _new_conn
    self, "Failed to establish a new connection: %s" % e
urllib3.exceptions.NewConnectionError: <urllib3.connection.HTTPConnection object at 0x2b2ac17998d0>: Failed to establish a new connection: [Errno 111] Connection refused

During handling of the above exception, another exception occurred:

Traceback (most recent call last):
  File "/home/sms8fr/.conda/envs/model/lib/python3.7/site-packages/requests/adapters.py", line 499, in send
    timeout=timeout,
  File "/home/sms8fr/.conda/envs/model/lib/python3.7/site-packages/urllib3/connectionpool.py", line 786, in urlopen
    method, url, error=e, _pool=self, _stacktrace=sys.exc_info()[2]
  File "/home/sms8fr/.conda/envs/model/lib/python3.7/site-packages/urllib3/util/retry.py", line 592, in increment
    raise MaxRetryError(_pool, url, error or ResponseError(cause))
urllib3.exceptions.MaxRetryError: HTTPConnectionPool(host='udc-aj38-17c1', port=5000): Max retries exceeded with url: /reset (Caused by NewConnectionError('<urllib3.connection.HTTPConnection object at 0x2b2ac17998d0>: Failed to establish a new connection: [Errno 111] Connection refused'))

During handling of the above exception, another exception occurred:

Traceback (most recent call last):
  File "test.py", line 20, in <module>
    data = requests.get(url.format("reset"))
  File "/home/sms8fr/.conda/envs/model/lib/python3.7/site-packages/requests/api.py", line 73, in get
    return request("get", url, params=params, **kwargs)
  File "/home/sms8fr/.conda/envs/model/lib/python3.7/site-packages/requests/api.py", line 59, in request
    return session.request(method=method, url=url, **kwargs)
  File "/home/sms8fr/.conda/envs/model/lib/python3.7/site-packages/requests/sessions.py", line 587, in request
    resp = self.send(prep, **send_kwargs)
  File "/home/sms8fr/.conda/envs/model/lib/python3.7/site-packages/requests/sessions.py", line 701, in send
    r = adapter.send(request, **kwargs)
  File "/home/sms8fr/.conda/envs/model/lib/python3.7/site-packages/requests/adapters.py", line 565, in send
    raise ConnectionError(e, request=request)
requests.exceptions.ConnectionError: HTTPConnectionPool(host='udc-aj38-17c1', port=5000): Max retries exceeded with url: /reset (Caused by NewConnectionError('<urllib3.connection.HTTPConnection object at 0x2b2ac17998d0>: Failed to establish a new connection: [Errno 111] Connection refused'))
